Loading python/3.7.3
  Loading requirement: tcl/8.6.8 gcc/8.3.0
psutil is not installed. You will not be able to abort this experiment from the UI.
psutil is not installed. Hardware metrics will not be collected.
https://app.neptune.ai/dulayjm/psyphy-loss/e/PSYPHYLO-9
/afs/crc.nd.edu/user/j/jdulay/.local/lib/python3.7/site-packages/torch/nn/functional.py:718: UserWarning: Named tensors and all their associated APIs are an experimental feature and subject to change. Please do not use them for anything important until they are released as stable. (Triggered internally at  /pytorch/c10/core/TensorImpl.h:1156.)
  return torch.max_pool2d(input, kernel_size, stride, padding, dilation, ceil_mode)
Invalid metric value: nan for channel train_loss. Metrics with nan or +/-inf values will not be sent to server
Invalid metric value: nan for channel train_loss. Metrics with nan or +/-inf values will not be sent to server
Invalid metric value: nan for channel train_loss. Metrics with nan or +/-inf values will not be sent to server
Invalid metric value: nan for channel train_loss. Metrics with nan or +/-inf values will not be sent to server
Invalid metric value: nan for channel train_loss. Metrics with nan or +/-inf values will not be sent to server
Invalid metric value: nan for channel train_loss. Metrics with nan or +/-inf values will not be sent to server
Invalid metric value: nan for channel train_loss. Metrics with nan or +/-inf values will not be sent to server
Invalid metric value: nan for channel train_loss. Metrics with nan or +/-inf values will not be sent to server
Invalid metric value: nan for channel train_loss. Metrics with nan or +/-inf values will not be sent to server
Invalid metric value: nan for channel train_loss. Metrics with nan or +/-inf values will not be sent to server
Unexpected error in ping thread.
Traceback (most recent call last):
  File "/afs/crc.nd.edu/user/j/jdulay/.local/lib/python3.7/site-packages/urllib3/connectionpool.py", line 706, in urlopen
    chunked=chunked,
  File "/afs/crc.nd.edu/user/j/jdulay/.local/lib/python3.7/site-packages/urllib3/connectionpool.py", line 445, in _make_request
    six.raise_from(e, None)
  File "<string>", line 3, in raise_from
  File "/afs/crc.nd.edu/user/j/jdulay/.local/lib/python3.7/site-packages/urllib3/connectionpool.py", line 440, in _make_request
    httplib_response = conn.getresponse()
  File "/opt/crc/p/python/3.7.3/gcc/lib/python3.7/http/client.py", line 1321, in getresponse
    response.begin()
  File "/opt/crc/p/python/3.7.3/gcc/lib/python3.7/http/client.py", line 296, in begin
    version, status, reason = self._read_status()
  File "/opt/crc/p/python/3.7.3/gcc/lib/python3.7/http/client.py", line 257, in _read_status
    line = str(self.fp.readline(_MAXLINE + 1), "iso-8859-1")
  File "/opt/crc/p/python/3.7.3/gcc/lib/python3.7/socket.py", line 589, in readinto
    return self._sock.recv_into(b)
  File "/opt/crc/p/python/3.7.3/gcc/lib/python3.7/ssl.py", line 1052, in recv_into
    return self.read(nbytes, buffer)
  File "/opt/crc/p/python/3.7.3/gcc/lib/python3.7/ssl.py", line 911, in read
    return self._sslobj.read(len, buffer)
ConnectionResetError: [Errno 104] Connection reset by peer

During handling of the above exception, another exception occurred:

Traceback (most recent call last):
  File "/afs/crc.nd.edu/user/j/jdulay/.local/lib/python3.7/site-packages/requests/adapters.py", line 449, in send
    timeout=timeout
  File "/afs/crc.nd.edu/user/j/jdulay/.local/lib/python3.7/site-packages/urllib3/connectionpool.py", line 756, in urlopen
    method, url, error=e, _pool=self, _stacktrace=sys.exc_info()[2]
  File "/afs/crc.nd.edu/user/j/jdulay/.local/lib/python3.7/site-packages/urllib3/util/retry.py", line 532, in increment
    raise six.reraise(type(error), error, _stacktrace)
  File "/afs/crc.nd.edu/user/j/jdulay/.local/lib/python3.7/site-packages/urllib3/packages/six.py", line 769, in reraise
    raise value.with_traceback(tb)
  File "/afs/crc.nd.edu/user/j/jdulay/.local/lib/python3.7/site-packages/urllib3/connectionpool.py", line 706, in urlopen
    chunked=chunked,
  File "/afs/crc.nd.edu/user/j/jdulay/.local/lib/python3.7/site-packages/urllib3/connectionpool.py", line 445, in _make_request
    six.raise_from(e, None)
  File "<string>", line 3, in raise_from
  File "/afs/crc.nd.edu/user/j/jdulay/.local/lib/python3.7/site-packages/urllib3/connectionpool.py", line 440, in _make_request
    httplib_response = conn.getresponse()
  File "/opt/crc/p/python/3.7.3/gcc/lib/python3.7/http/client.py", line 1321, in getresponse
    response.begin()
  File "/opt/crc/p/python/3.7.3/gcc/lib/python3.7/http/client.py", line 296, in begin
    version, status, reason = self._read_status()
  File "/opt/crc/p/python/3.7.3/gcc/lib/python3.7/http/client.py", line 257, in _read_status
    line = str(self.fp.readline(_MAXLINE + 1), "iso-8859-1")
  File "/opt/crc/p/python/3.7.3/gcc/lib/python3.7/socket.py", line 589, in readinto
    return self._sock.recv_into(b)
  File "/opt/crc/p/python/3.7.3/gcc/lib/python3.7/ssl.py", line 1052, in recv_into
    return self.read(nbytes, buffer)
  File "/opt/crc/p/python/3.7.3/gcc/lib/python3.7/ssl.py", line 911, in read
    return self._sslobj.read(len, buffer)
urllib3.exceptions.ProtocolError: ('Connection aborted.', ConnectionResetError(104, 'Connection reset by peer'))

During handling of the above exception, another exception occurred:

Traceback (most recent call last):
  File "/afs/crc.nd.edu/user/j/jdulay/.local/lib/python3.7/site-packages/bravado/http_future.py", line 124, in wrapper
    return func(self, *args, **kwargs)
  File "/afs/crc.nd.edu/user/j/jdulay/.local/lib/python3.7/site-packages/bravado/http_future.py", line 291, in _get_incoming_response
    inner_response = self.future.result(timeout=timeout)
  File "/afs/crc.nd.edu/user/j/jdulay/.local/lib/python3.7/site-packages/bravado/requests_client.py", line 270, in result
    **settings
  File "/afs/crc.nd.edu/user/j/jdulay/.local/lib/python3.7/site-packages/requests/sessions.py", line 655, in send
    r = adapter.send(request, **kwargs)
  File "/afs/crc.nd.edu/user/j/jdulay/.local/lib/python3.7/site-packages/requests/adapters.py", line 498, in send
    raise ConnectionError(err, request=request)
requests.exceptions.ConnectionError: ('Connection aborted.', ConnectionResetError(104, 'Connection reset by peer'))

During handling of the above exception, another exception occurred:

Traceback (most recent call last):
  File "/afs/crc.nd.edu/user/j/jdulay/.local/lib/python3.7/site-packages/neptune/internal/threads/ping_thread.py", line 37, in run
    self.__backend.ping_experiment(self.__experiment)
  File "/afs/crc.nd.edu/user/j/jdulay/.local/lib/python3.7/site-packages/neptune/internal/api_clients/hosted_api_clients/hosted_alpha_leaderboard_api_client.py", line 392, in ping_experiment
    self.leaderboard_swagger_client.api.ping(experimentId=str(experiment.internal_id)).response().result
  File "/afs/crc.nd.edu/user/j/jdulay/.local/lib/python3.7/site-packages/bravado/http_future.py", line 239, in response
    six.reraise(*sys.exc_info())
  File "/afs/crc.nd.edu/user/j/jdulay/.local/lib/python3.7/site-packages/six.py", line 719, in reraise
    raise value
  File "/afs/crc.nd.edu/user/j/jdulay/.local/lib/python3.7/site-packages/bravado/http_future.py", line 197, in response
    incoming_response = self._get_incoming_response(timeout)
  File "/afs/crc.nd.edu/user/j/jdulay/.local/lib/python3.7/site-packages/bravado/http_future.py", line 126, in wrapper
    self.future._raise_connection_error(exception)
  File "/afs/crc.nd.edu/user/j/jdulay/.local/lib/python3.7/site-packages/bravado/http_future.py", line 91, in _raise_connection_error
    self._raise_error(BravadoConnectionError, 'ConnectionError', exception)
  File "/afs/crc.nd.edu/user/j/jdulay/.local/lib/python3.7/site-packages/bravado/http_future.py", line 82, in _raise_error
    sys.exc_info()[2],
  File "/afs/crc.nd.edu/user/j/jdulay/.local/lib/python3.7/site-packages/six.py", line 718, in reraise
    raise value.with_traceback(tb)
  File "/afs/crc.nd.edu/user/j/jdulay/.local/lib/python3.7/site-packages/bravado/http_future.py", line 124, in wrapper
    return func(self, *args, **kwargs)
  File "/afs/crc.nd.edu/user/j/jdulay/.local/lib/python3.7/site-packages/bravado/http_future.py", line 291, in _get_incoming_response
    inner_response = self.future.result(timeout=timeout)
  File "/afs/crc.nd.edu/user/j/jdulay/.local/lib/python3.7/site-packages/bravado/requests_client.py", line 270, in result
    **settings
  File "/afs/crc.nd.edu/user/j/jdulay/.local/lib/python3.7/site-packages/requests/sessions.py", line 655, in send
    r = adapter.send(request, **kwargs)
  File "/afs/crc.nd.edu/user/j/jdulay/.local/lib/python3.7/site-packages/requests/adapters.py", line 498, in send
    raise ConnectionError(err, request=request)
bravado.http_future.RequestsFutureAdapterConnectionError
Invalid metric value: nan for channel train_loss. Metrics with nan or +/-inf values will not be sent to server
Invalid metric value: nan for channel train_loss. Metrics with nan or +/-inf values will not be sent to server
Invalid metric value: nan for channel train_loss. Metrics with nan or +/-inf values will not be sent to server
Invalid metric value: nan for channel train_loss. Metrics with nan or +/-inf values will not be sent to server
Invalid metric value: nan for channel train_loss. Metrics with nan or +/-inf values will not be sent to server
Invalid metric value: nan for channel train_loss. Metrics with nan or +/-inf values will not be sent to server
Invalid metric value: nan for channel train_loss. Metrics with nan or +/-inf values will not be sent to server
Invalid metric value: nan for channel train_loss. Metrics with nan or +/-inf values will not be sent to server
Invalid metric value: nan for channel train_loss. Metrics with nan or +/-inf values will not be sent to server
Invalid metric value: nan for channel train_loss. Metrics with nan or +/-inf values will not be sent to server
device is cuda
epoch 0 accuracy: 1.49%
running loss: nan
epoch 1 accuracy: 1.49%
running loss: nan
epoch 2 accuracy: 1.49%
running loss: nan
epoch 3 accuracy: 1.49%
running loss: nan
epoch 4 accuracy: 1.49%
running loss: nan
epoch 5 accuracy: 1.49%
running loss: nan
epoch 6 accuracy: 1.49%
running loss: nan
epoch 7 accuracy: 1.49%
running loss: nan
epoch 8 accuracy: 1.49%
running loss: nan
epoch 9 accuracy: 1.49%
running loss: nan
epoch 10 accuracy: 1.49%
running loss: nan
epoch 11 accuracy: 1.49%
running loss: nan
epoch 12 accuracy: 1.49%
running loss: nan
epoch 13 accuracy: 1.49%
running loss: nan
epoch 14 accuracy: 1.49%
running loss: nan
epoch 15 accuracy: 1.49%
running loss: nan
epoch 16 accuracy: 1.49%
running loss: nan
epoch 17 accuracy: 1.49%
running loss: nan
epoch 18 accuracy: 1.49%
running loss: nan
epoch 19 accuracy: 1.49%
running loss: nan
finished training
